import requests
import logging

def task_func(repo_url: str) -> dict:
    """
    Fetches and returns information about a GitHub repository using its API URL.
    
    Args:
        repo_url (str): The URL of the GitHub repository API.
    
    Returns:
        dict: A dictionary containing information about the GitHub repository.
    
    Raises:
        requests.exceptions.HTTPError: If an HTTP error occurs, particularly when the GitHub API rate limit is exceeded.
        requests.exceptions.RequestException: For other general issues encountered during the API request.
    """
    try:
        response = requests.get(repo_url)
        response.raise_for_status()  # Raises an HTTPError for bad responses (4xx and 5xx)
        
        repo_info = response.json()
        
        # Check for a large number of open issues
        open_issues_count = repo_info.get('open_issues_count', 0)
        if open_issues_count > 100:
            logging.warning(f"Warning: The repository has a large number of open issues: {open_issues_count}")
        
        return repo_info
    
    except requests.exceptions.HTTPError as http_err:
        if response.status_code == 403 and 'rate limit' in response.text.lower():
            logging.error("GitHub API rate limit exceeded.")
        else:
            logging.error(f"HTTP error occurred: {http_err}")
        raise http_err
    
    except requests.exceptions.RequestException as req_err:
        logging.error(f"Request error occurred: {req_err}")
        raise req_err

# Example usage:
# repo_url = "https://api.github.com/repos/octocat/Hello-World"
# repo_info = task_func(repo_url)
# print(repo_info)
import unittest
from unittest.mock import patch, MagicMock
from io import StringIO
from contextlib import redirect_stdout
class TestCases(unittest.TestCase):
    """Test cases for task_func."""
    @patch("requests.get")
    def test_successful_response(self, mock_get):
        """
        Test task_func with a successful response.
        """
        mock_get.return_value = MagicMock(
            status_code=200, json=lambda: {"open_issues_count": 5000}
        )
        response = task_func("https://api.github.com/repos/psf/requests")
        self.assertIn("open_issues_count", response)
        self.assertEqual(response["open_issues_count"], 5000)
    @patch("requests.get")
    @patch('logging.warning')
    def test_response_with_more_than_10000_issues(self, mock_warning, mock_get):
        """
        Test task_func with a response indicating more than 10000 open issues.
        """
        mock_get.return_value = MagicMock(
            status_code=200, json=lambda: {"open_issues_count": 15000}
        )
        
        response = task_func("https://api.github.com/repos/psf/requests")
        
        mock_warning.assert_called_once_with("The repository has more than 10000 open issues.")
        self.assertEqual(response["open_issues_count"], 15000)
    @patch("requests.get")
    def test_api_rate_limit_exceeded(self, mock_get):
        """
        Test task_func handling API rate limit exceeded error.
        """
        mock_get.return_value = MagicMock(
            status_code=403, json=lambda: {"message": "API rate limit exceeded"}
        )
        with self.assertRaises(Exception) as context:
            task_func("https://api.github.com/repos/psf/requests")
        self.assertIn("API rate limit exceeded", str(context.exception))
    @patch("requests.get")
    def test_http_error(self, mock_get):
        """
        Test task_func handling HTTP errors.
        """
        mock_get.side_effect = requests.exceptions.HTTPError(
            "404 Client Error: Not Found for url"
        )
        with self.assertRaises(Exception) as context:
            task_func("https://api.github.com/repos/psf/requests")
        self.assertIn("404 Client Error", str(context.exception))
    @patch("requests.get")
    def test_invalid_url(self, mock_get):
        """
        Test task_func with an invalid URL.
        """
        mock_get.side_effect = requests.exceptions.InvalidURL("Invalid URL")
        with self.assertRaises(Exception) as context:
            task_func("invalid_url")
        self.assertIn("Invalid URL", str(context.exception))


if __name__ == '__main__':
    unittest.main(argv=['first-arg-is-ignored'], exit=False)